2020-10-08 14:31:49.969619 [func:main:server](started on): 0.0.0.0:2333
2020-10-08 14:36:42.011977 [func:handle_incoming]				Accepted Client: <socket.socket fd=9, family=AddressFamily.AF_INET, type=SocketKind.SOCK_STREAM, proto=0, laddr=('10.0.4.17', 2333)>
2020-10-08 14:36:42.012349 [func:handle_incoming]				Accepted Client: <socket.socket fd=10, family=AddressFamily.AF_INET, type=SocketKind.SOCK_STREAM, proto=0, laddr=('10.0.4.17', 2333), raddr=('210.30.97.199', 35780)>
ERROR:root:function _subthread_handle_readable was called with
    args=(<esockets.socket_server.SocketServer object at 0x7f9757448eb8>, <socket.socket fd=9, family=AddressFamily.AF_INET, type=2049, proto=0, laddr=('10.0.4.17', 2333)>)
    kwargs={}
    and exited with error:
    --------------------------------------------------
    Traceback (most recent call last):
      File "/home/ubuntu/.local/lib/python3.6/site-packages/esockets/socket_server.py", line 36, in wrapped_f
        f(*args, **kwargs)
      File "/home/ubuntu/.local/lib/python3.6/site-packages/esockets/socket_server.py", line 154, in _subthread_handle_readable
        if self.handle_readable(conn):
      File "server.py", line 161, in handle_readable
        data = client.recv(1028)
    ConnectionResetError: [Errno 104] Connection reset by peer
    --------------------------------------------------

Exception in thread Thread-3:
Traceback (most recent call last):
  File "/usr/lib/python3.6/threading.py", line 916, in _bootstrap_inner
    self.run()
  File "/usr/lib/python3.6/threading.py", line 864, in run
    self._target(*self._args, **self._kwargs)
  File "/home/ubuntu/.local/lib/python3.6/site-packages/maxthreads/maxthreads.py", line 165, in _loop
    target()
  File "/home/ubuntu/.local/lib/python3.6/site-packages/maxthreads/maxthreads.py", line 67, in __call__
    self.target(*self.args, **self.kwargs)
  File "/home/ubuntu/.local/lib/python3.6/site-packages/esockets/socket_server.py", line 36, in wrapped_f
    f(*args, **kwargs)
  File "/home/ubuntu/.local/lib/python3.6/site-packages/esockets/socket_server.py", line 154, in _subthread_handle_readable
    if self.handle_readable(conn):
  File "server.py", line 161, in handle_readable
    data = client.recv(1028)
ConnectionResetError: [Errno 104] Connection reset by peer

2020-10-08 14:36:50.914600 [func:handle_readable:Handle]		Received Client Struct: <socket.socket fd=10, family=AddressFamily.AF_INET, type=2049, proto=0, laddr=('10.0.4.17', 2333), raddr=('210.30.97.199', 35780)>
2020-10-08 14:36:50.914670 [func:handle_readable:Handle]		Received Client: '210.30.97.199'  35780
2020-10-08 14:36:50.914679 [func:handle_readable:Handle]		Client Received: b'000000000000000'
2020-10-08 14:36:50.914695 [func:handle_readable:IMEI]Received IMEI
2020-10-08 14:36:50.914701 [func:handle_readable:IMEI](strdata): 000000000000000
2020-10-08 14:37:26.330119 [func:handle_readable:Handle]		Received Client Struct: <socket.socket fd=10, family=AddressFamily.AF_INET, type=2049, proto=0, laddr=('10.0.4.17', 2333), raddr=('210.30.97.199', 35780)>
2020-10-08 14:37:26.330201 [func:handle_readable:Handle]		Received Client: '210.30.97.199'  35780
2020-10-08 14:37:26.330210 [func:handle_readable:Handle]		Client Received: b''
2020-10-08 14:37:26.330218 [func:handle_readable:None]
